<?xml version="1.0" ?>
<!-- =================================================================================== -->
<!-- |    This document was autogenerated by xacro from steering_thrusters.xacro       | -->
<!-- |    EDITING THIS FILE BY HAND IS NOT RECOMMENDED                                 | -->
<!-- =================================================================================== -->
<!-- STL-version of the URDF, used with gazebo for dynamic simulation  -->
<robot name="steering_auv" xmlns:xacro="http://www.ros.org/wiki/xacro">
  <!-- Plugin list -->
  <gazebo>
    <!-- Gazebo plugin listens to the body-->
    <plugin filename="libfreefloating_gazebo_control.so" name="freefloating_gazebo_control">
      <switchService>switch</switchService>
      <updateRate>100</updateRate>
      <link>base_link</link>
      <!--    these two thrusters are actually orientable, so the map should not be hard-coded 
                        the thruster name is the name of the corresponding link -->
      <thruster>
        <effort>30</effort>
        <name>fwd_left</name>
      </thruster>
      <thruster>
        <effort>30</effort>
        <name>fwd_right</name>
      </thruster>
      <!--    these thrusters are fixed and the map can be hard-coded 
                        they will be given a name (thr2 to thr4)  -->
      <thruster>
        <map>0 1 0 0 0 0</map>
        <effort>30</effort>
      </thruster>
      <thruster>
        <map>0 0 -1 0 -0.45 0</map>
        <effort>30</effort>
      </thruster>
      <thruster>
        <map>0 0 -1 0 0.45 0</map>
        <effort>30</effort>
      </thruster>
    </plugin>
  </gazebo>
  <link name="base_link">
    <visual>
      <origin rpy="0 -1.57079632679 0"/>
      <geometry>
        <cylinder length="1.5" radius="0.13"/>
      </geometry>
    </visual>
    <inertial>
      <origin rpy="0 -1.57079632679 0" xyz="0 0 -0.065"/>
      <mass value="25"/>
      <inertia ixx="4.793125" ixy="0.0" ixz="0.0" iyy="4.793125" iyz="0.0" izz="0.21125"/>
    </inertial>
    <buoyancy>
      <compensation>1.01</compensation>
      <origin xyz="0 0 0"/>
      <limit radius="0.13"/>
      <damping rpy="20 50 50" xyz="60 100 100"/>
    </buoyancy>
  </link>
  <joint name="fwd_left_j" type="revolute">
    <parent link="base_link"/>
    <child link="fwd_left"/>
    <origin rpy="0 1.57079632679 0" xyz="-0.5 0.18 0"/>
    <dynamics damping="10.0"/>
    <axis xyz="0 1 0"/>
    <limit effort="30" lower="-1.57079632679" upper="1.57079632679" velocity="5.0"/>
  </joint>
  <link name="fwd_left">
    <buoyancy>
      <compensation>1.0</compensation>
    </buoyancy>
    <visual name="fwd_left_1">
      <geometry>
        <cylinder length="0.1" radius="0.02"/>
      </geometry>
      <material name="black">
        <color rgba="0 0 0 1"/>
      </material>
    </visual>
    <visual name="fwd_left_2">
      <origin xyz="0 0 -0.065"/>
      <geometry>
        <cylinder length="0.03" radius="0.05"/>
      </geometry>
      <material name="black">
        <color rgba="0 0 0 1"/>
      </material>
    </visual>
    <inertial>
      <mass value=".1"/>
      <inertia ixx=".1" ixy="0.0" ixz="0.0" iyy=".1" iyz="0.0" izz=".1"/>
    </inertial>
  </link>
  <joint name="fwd_left" type="prismatic">
    <parent link="fwd_left"/>
    <child link="fwd_left_virt"/>
    <axis xyz="0 0 1"/>
    <limit effort="30" lower="-1.57079632679" upper="1.57079632679" velocity="5.0"/>
  </joint>
  <link name="fwd_left_virt"/>
  <gazebo reference="fwd_left">
    <material>Gazebo/Black</material>
  </gazebo>
  <joint name="fwd_right_j" type="revolute">
    <parent link="base_link"/>
    <child link="fwd_right"/>
    <origin rpy="0 1.57079632679 0" xyz="-0.5 -0.18 0"/>
    <dynamics damping="10.0"/>
    <axis xyz="0 1 0"/>
    <limit effort="30" lower="-1.57079632679" upper="1.57079632679" velocity="5.0"/>
  </joint>
  <link name="fwd_right">
    <buoyancy>
      <compensation>1.0</compensation>
    </buoyancy>
    <visual name="fwd_right_1">
      <geometry>
        <cylinder length="0.1" radius="0.02"/>
      </geometry>
      <material name="black">
        <color rgba="0 0 0 1"/>
      </material>
    </visual>
    <visual name="fwd_right_2">
      <origin xyz="0 0 -0.065"/>
      <geometry>
        <cylinder length="0.03" radius="0.05"/>
      </geometry>
      <material name="black">
        <color rgba="0 0 0 1"/>
      </material>
    </visual>
    <inertial>
      <mass value=".1"/>
      <inertia ixx=".1" ixy="0.0" ixz="0.0" iyy=".1" iyz="0.0" izz=".1"/>
    </inertial>
  </link>
  <joint name="fwd_right" type="prismatic">
    <parent link="fwd_right"/>
    <child link="fwd_right_virt"/>
    <axis xyz="0 0 1"/>
    <limit effort="30" lower="-1.57079632679" upper="1.57079632679" velocity="5.0"/>
  </joint>
  <link name="fwd_right_virt"/>
  <gazebo reference="fwd_right">
    <material>Gazebo/Black</material>
  </gazebo>
</robot>

